2022-11-04 11:19:14,385 DEBUG    root            Loaded Command Group: ['gcloud', 'source']
2022-11-04 11:19:14,404 DEBUG    root            Loaded Command Group: ['gcloud', 'source', 'repos']
2022-11-04 11:19:14,576 DEBUG    root            Loaded Command Group: ['gcloud', 'source', 'repos', 'create']
2022-11-04 11:19:14,585 DEBUG    root            Running [gcloud.source.repos.create] with arguments: [REPOSITORY_NAME: "house-insight"]
2022-11-04 11:19:14,637 DEBUG    google.auth.transport.requests Making request: GET http://metadata.google.internal/computeMetadata/v1/instance/service-accounts/554650739751-compute@developer.gserviceaccount.com/?recursive=true
2022-11-04 11:19:14,640 DEBUG    urllib3.connectionpool Starting new HTTP connection (1): metadata.google.internal:80
2022-11-04 11:19:14,642 DEBUG    urllib3.connectionpool http://metadata.google.internal:80 "GET /computeMetadata/v1/instance/service-accounts/554650739751-compute@developer.gserviceaccount.com/?recursive=true HTTP/1.1" 200 155
2022-11-04 11:19:14,643 DEBUG    google.auth.transport.requests Making request: GET http://metadata.google.internal/computeMetadata/v1/instance/service-accounts/554650739751-compute@developer.gserviceaccount.com/token
2022-11-04 11:19:14,645 DEBUG    urllib3.connectionpool http://metadata.google.internal:80 "GET /computeMetadata/v1/instance/service-accounts/554650739751-compute@developer.gserviceaccount.com/token HTTP/1.1" 200 266
2022-11-04 11:19:14,658 DEBUG    google.auth.transport.requests Making request: GET http://metadata.google.internal/computeMetadata/v1/instance/service-accounts/554650739751-compute@developer.gserviceaccount.com/?recursive=true
2022-11-04 11:19:14,659 DEBUG    urllib3.connectionpool Starting new HTTP connection (1): metadata.google.internal:80
2022-11-04 11:19:14,661 DEBUG    urllib3.connectionpool http://metadata.google.internal:80 "GET /computeMetadata/v1/instance/service-accounts/554650739751-compute@developer.gserviceaccount.com/?recursive=true HTTP/1.1" 200 155
2022-11-04 11:19:14,662 DEBUG    google.auth.transport.requests Making request: GET http://metadata.google.internal/computeMetadata/v1/instance/service-accounts/554650739751-compute@developer.gserviceaccount.com/token
2022-11-04 11:19:14,664 DEBUG    urllib3.connectionpool http://metadata.google.internal:80 "GET /computeMetadata/v1/instance/service-accounts/554650739751-compute@developer.gserviceaccount.com/token HTTP/1.1" 200 266
2022-11-04 11:19:14,677 DEBUG    urllib3.connectionpool Starting new HTTPS connection (1): sourcerepo.googleapis.com:443
2022-11-04 11:19:15,145 DEBUG    urllib3.connectionpool https://sourcerepo.googleapis.com:443 "POST /v1/projects/insight-tool-321814/repos?alt=json HTTP/1.1" 403 None
2022-11-04 11:19:15,155 DEBUG    root            (gcloud.source.repos.create) ResponseError: status=[PERMISSION_DENIED], code=[403], message=[User [554650739751-compute@developer.gserviceaccount.com] does not have permission to access projects instance [insight-tool-321814] (or it may not exist): The caller does not have permission]. 
Traceback (most recent call last):
  File "/usr/lib/google-cloud-sdk/lib/surface/source/repos/create.py", line 92, in Run
    repo = source_handler.CreateRepo(res)
  File "/usr/lib/google-cloud-sdk/lib/googlecloudsdk/api_lib/source/sourcerepo.py", line 131, in CreateRepo
    return self._client.projects_repos.Create(request)
  File "/usr/lib/google-cloud-sdk/lib/googlecloudsdk/generated_clients/apis/sourcerepo/v1/sourcerepo_v1_client.py", line 65, in Create
    return self._RunMethod(
  File "/usr/bin/../lib/google-cloud-sdk/lib/third_party/apitools/base/py/base_api.py", line 737, in _RunMethod
    return self.ProcessHttpResponse(method_config, http_response, request)
  File "/usr/bin/../lib/google-cloud-sdk/lib/third_party/apitools/base/py/base_api.py", line 743, in ProcessHttpResponse
    self.__ProcessHttpResponse(method_config, http_response, request))
  File "/usr/bin/../lib/google-cloud-sdk/lib/third_party/apitools/base/py/base_api.py", line 609, in __ProcessHttpResponse
    raise exceptions.HttpError.FromResponse(
apitools.base.py.exceptions.HttpForbiddenError: HttpError accessing <https://sourcerepo.googleapis.com/v1/projects/insight-tool-321814/repos?alt=json>: response: <{'vary': 'Origin, X-Origin, Referer', 'content-type': 'application/json; charset=UTF-8', 'content-encoding': 'gzip', 'date': 'Fri, 04 Nov 2022 11:19:15 GMT', 'server': 'ESF', 'cache-control': 'private', 'x-xss-protection': '0', 'x-frame-options': 'SAMEORIGIN', 'x-content-type-options': 'nosniff', 'transfer-encoding': 'chunked', 'status': 403}>, content <{
  "error": {
    "code": 403,
    "message": "The caller does not have permission",
    "status": "PERMISSION_DENIED",
    "details": [
      {
        "@type": "type.googleapis.com/google.rpc.RequestInfo",
        "requestId": "1d7c23d62e7a40ae884c1f722ba04b87"
      }
    ]
  }
}
>

During handling of the above exception, another exception occurred:

Traceback (most recent call last):
  File "/usr/lib/google-cloud-sdk/lib/googlecloudsdk/calliope/cli.py", line 987, in Execute
    resources = calliope_command.Run(cli=self, args=args)
  File "/usr/lib/google-cloud-sdk/lib/googlecloudsdk/calliope/backend.py", line 807, in Run
    resources = command_instance.Run(args)
  File "/usr/lib/google-cloud-sdk/lib/surface/source/repos/create.py", line 105, in Run
    raise exc
googlecloudsdk.calliope.exceptions.HttpException: ResponseError: status=[PERMISSION_DENIED], code=[403], message=[User [554650739751-compute@developer.gserviceaccount.com] does not have permission to access projects instance [insight-tool-321814] (or it may not exist): The caller does not have permission]. 
2022-11-04 11:19:15,207 ERROR    root            (gcloud.source.repos.create) ResponseError: status=[PERMISSION_DENIED], code=[403], message=[User [554650739751-compute@developer.gserviceaccount.com] does not have permission to access projects instance [insight-tool-321814] (or it may not exist): The caller does not have permission]. 
